Traceback (most recent call last):
  File "/Library/Frameworks/Python.framework/Versions/3.10/lib/python3.10/site-packages/jupyter_cache/executors/utils.py", line 58, in single_nb_execution
    executenb(
  File "/Library/Frameworks/Python.framework/Versions/3.10/lib/python3.10/site-packages/nbclient/client.py", line 1319, in execute
    return NotebookClient(nb=nb, resources=resources, km=km, **kwargs).execute()
  File "/Library/Frameworks/Python.framework/Versions/3.10/lib/python3.10/site-packages/jupyter_core/utils/__init__.py", line 165, in wrapped
    return loop.run_until_complete(inner)
  File "/Library/Frameworks/Python.framework/Versions/3.10/lib/python3.10/asyncio/base_events.py", line 649, in run_until_complete
    return future.result()
  File "/Library/Frameworks/Python.framework/Versions/3.10/lib/python3.10/site-packages/nbclient/client.py", line 709, in async_execute
    await self.async_execute_cell(
  File "/Library/Frameworks/Python.framework/Versions/3.10/lib/python3.10/site-packages/nbclient/client.py", line 1062, in async_execute_cell
    await self._check_raise_for_error(cell, cell_index, exec_reply)
  File "/Library/Frameworks/Python.framework/Versions/3.10/lib/python3.10/site-packages/nbclient/client.py", line 918, in _check_raise_for_error
    raise CellExecutionError.from_cell_and_msg(cell, exec_reply_content)
nbclient.exceptions.CellExecutionError: An error occurred while executing the following cell:
------------------
import pandas as pd
import numpy as np
import matplotlib.pyplot as plt
plt.rc('figure', figsize=(20, 10))
from IPython.display import set_matplotlib_formats
set_matplotlib_formats('png', 'pdf')
from operator import itemgetter
import networkx as nx
from networkx.algorithms import community 

#This part of networkx, 
# for community detection, needs to be imported separately.
import nbconvert
import csv

# <img src="xxxx.png">
------------------


[0;31m---------------------------------------------------------------------------[0m
[0;31mModuleNotFoundError[0m                       Traceback (most recent call last)
Cell [0;32mIn[1], line 3[0m
[1;32m      1[0m [38;5;28;01mimport[39;00m[38;5;250m [39m[38;5;21;01mpandas[39;00m[38;5;250m [39m[38;5;28;01mas[39;00m[38;5;250m [39m[38;5;21;01mpd[39;00m
[1;32m      2[0m [38;5;28;01mimport[39;00m[38;5;250m [39m[38;5;21;01mnumpy[39;00m[38;5;250m [39m[38;5;28;01mas[39;00m[38;5;250m [39m[38;5;21;01mnp[39;00m
[0;32m----> 3[0m [38;5;28;01mimport[39;00m[38;5;250m [39m[38;5;21;01mmatplotlib[39;00m[38;5;21;01m.[39;00m[38;5;21;01mpyplot[39;00m[38;5;250m [39m[38;5;28;01mas[39;00m[38;5;250m [39m[38;5;21;01mplt[39;00m
[1;32m      4[0m plt[38;5;241m.[39mrc([38;5;124m'[39m[38;5;124mfigure[39m[38;5;124m'[39m, figsize[38;5;241m=[39m([38;5;241m20[39m, [38;5;241m10[39m))
[1;32m      5[0m [38;5;28;01mfrom[39;00m[38;5;250m [39m[38;5;21;01mIPython[39;00m[38;5;21;01m.[39;00m[38;5;21;01mdisplay[39;00m[38;5;250m [39m[38;5;28;01mimport[39;00m set_matplotlib_formats

[0;31mModuleNotFoundError[0m: No module named 'matplotlib'

